<?xml version="1.0"?>
<robot xmlns:xacro="http://www.ros.org/wiki/xacro" name="simple_humanoid">

  <!-- Define properties -->
  <xacro:property name="M_PI" value="3.1415926535897931" />
  <xacro:property name="torso_mass" value="10.0" />
  <xacro:property name="head_mass" value="2.0" />
  <xacro:property name="arm_mass" value="1.5" />
  <xacro:property name="leg_mass" value="3.0" />

  <!-- Base link -->
  <link name="base_link" />

  <!-- Torso -->
  <link name="torso">
    <inertial>
      <mass value="${torso_mass}" />
      <origin xyz="0 0 0.2" rpy="0 0 0" />
      <inertia ixx="0.4" ixy="0.0" ixz="0.0" iyy="0.4" iyz="0.0" izz="0.2" />
    </inertial>
    <visual>
      <origin xyz="0 0 0.2" rpy="0 0 0" />
      <geometry>
        <cylinder length="0.4" radius="0.15" />
      </geometry>
      <material name="light_grey">
        <color rgba="0.7 0.7 0.7 1.0" />
      </material>
    </visual>
    <collision>
      <origin xyz="0 0 0.2" rpy="0 0 0" />
      <geometry>
        <cylinder length="0.4" radius="0.15" />
      </geometry>
    </collision>
  </link>

  <joint name="base_to_torso" type="fixed">
    <parent link="base_link" />
    <child link="torso" />
    <origin xyz="0 0 0" rpy="0 0 0" />
  </joint>

  <!-- Head -->
  <link name="head">
    <inertial>
      <mass value="${head_mass}" />
      <origin xyz="0 0 0.1" rpy="0 0 0" />
      <inertia ixx="0.02" ixy="0.0" ixz="0.0" iyy="0.02" iyz="0.0" izz="0.02" />
    </inertial>
    <visual>
      <origin xyz="0 0 0.1" rpy="0 0 0" />
      <geometry>
        <sphere radius="0.1" />
      </geometry>
      <material name="white">
        <color rgba="1.0 1.0 1.0 1.0" />
      </material>
    </visual>
    <collision>
      <origin xyz="0 0 0.1" rpy="0 0 0" />
      <geometry>
        <sphere radius="0.1" />
      </geometry>
    </collision>
  </link>

  <!-- Neck Joint -->
  <joint name="neck_joint" type="revolute">
    <parent link="torso" />
    <child link="head" />
    <origin xyz="0.0 0.0 0.4" rpy="0 0 0" />
    <axis xyz="0 1 0" />
    <limit lower="${-M_PI/3}" upper="${M_PI/3}" effort="10" velocity="2.0" />
  </joint>

  <!-- Left Arm Macro -->
  <xacro:macro name="simple_arm" params="prefix parent *origin">
    <link name="${prefix}_upper_arm">
      <inertial>
        <mass value="${arm_mass}" />
        <origin xyz="0 0 -0.15" rpy="0 0 0" />
        <inertia ixx="0.01" ixy="0.0" ixz="0.0" iyy="0.01" iyz="0.0" izz="0.005" />
      </inertial>
      <visual>
        <origin xyz="0 0 -0.15" rpy="0 0 0" />
        <geometry>
          <cylinder length="0.3" radius="0.05" />
        </geometry>
        <material name="blue">
          <color rgba="0 0 0.8 1.0" />
        </material>
      </visual>
      <collision>
        <origin xyz="0 0 -0.15" rpy="0 0 0" />
        <geometry>
          <cylinder length="0.3" radius="0.05" />
        </geometry>
      </collision>
    </link>

    <joint name="${prefix}_shoulder_joint" type="revolute">
      <parent link="${parent}" />
      <child link="${prefix}_upper_arm" />
      <xacro:insert_block name="origin" />
      <axis xyz="0 0 1" />
      <limit lower="${-M_PI/2}" upper="${M_PI/2}" effort="15" velocity="1.5" />
    </joint>

    <link name="${prefix}_lower_arm">
      <inertial>
        <mass value="${arm_mass * 0.7}" />
        <origin xyz="0 0 -0.12" rpy="0 0 0" />
        <inertia ixx="0.005" ixy="0.0" ixz="0.0" iyy="0.005" iyz="0.0" izz="0.003" />
      </inertial>
      <visual>
        <origin xyz="0 0 -0.12" rpy="0 0 0" />
        <geometry>
          <cylinder length="0.24" radius="0.04" />
        </geometry>
        <material name="blue">
          <color rgba="0 0 0.8 1.0" />
        </material>
      </visual>
      <collision>
        <origin xyz="0 0 -0.12" rpy="0 0 0" />
        <geometry>
          <cylinder length="0.24" radius="0.04" />
        </geometry>
      </collision>
    </link>

    <joint name="${prefix}_elbow_joint" type="revolute">
      <parent link="${prefix}_upper_arm" />
      <child link="${prefix}_lower_arm" />
      <origin xyz="0.0 0.0 -0.3" rpy="0 0 0" />
      <axis xyz="0 0 1" />
      <limit lower="${-M_PI/2}" upper="${M_PI/2}" effort="10" velocity="1.0" />
    </joint>

    <link name="${prefix}_hand">
      <inertial>
        <mass value="${arm_mass * 0.3}" />
        <origin xyz="0 0 -0.05" rpy="0 0 0" />
        <inertia ixx="0.001" ixy="0.0" ixz="0.0" iyy="0.001" iyz="0.0" izz="0.001" />
      </inertial>
      <visual>
        <origin xyz="0 0 -0.05" rpy="0 0 0" />
        <geometry>
          <box size="0.08 0.08 0.1" />
        </geometry>
        <material name="light_grey">
          <color rgba="0.7 0.7 0.7 1.0" />
        </material>
      </visual>
      <collision>
        <origin xyz="0 0 -0.05" rpy="0 0 0" />
        <geometry>
          <box size="0.08 0.08 0.1" />
        </geometry>
      </collision>
    </link>

    <joint name="${prefix}_wrist_joint" type="revolute">
      <parent link="${prefix}_lower_arm" />
      <child link="${prefix}_hand" />
      <origin xyz="0.0 0.0 -0.24" rpy="0 0 0" />
      <axis xyz="0 1 0" />
      <limit lower="${-M_PI/3}" upper="${M_PI/3}" effort="5" velocity="1.0" />
    </joint>
  </xacro:macro>

  <!-- Right Arm Macro -->
  <xacro:macro name="simple_arm_right" params="prefix parent *origin">
    <link name="${prefix}_upper_arm">
      <inertial>
        <mass value="${arm_mass}" />
        <origin xyz="0 0 -0.15" rpy="0 0 0" />
        <inertia ixx="0.01" ixy="0.0" ixz="0.0" iyy="0.01" iyz="0.0" izz="0.005" />
      </inertial>
      <visual>
        <origin xyz="0 0 -0.15" rpy="0 0 0" />
        <geometry>
          <cylinder length="0.3" radius="0.05" />
        </geometry>
        <material name="blue">
          <color rgba="0 0 0.8 1.0" />
        </material>
      </visual>
      <collision>
        <origin xyz="0 0 -0.15" rpy="0 0 0" />
        <geometry>
          <cylinder length="0.3" radius="0.05" />
        </geometry>
      </collision>
    </link>

    <joint name="${prefix}_shoulder_joint" type="revolute">
      <parent link="${parent}" />
      <child link="${prefix}_upper_arm" />
      <xacro:insert_block name="origin" />
      <axis xyz="0 0 1" />
      <limit lower="${-M_PI/2}" upper="${M_PI/2}" effort="15" velocity="1.5" />
    </joint>

    <link name="${prefix}_lower_arm">
      <inertial>
        <mass value="${arm_mass * 0.7}" />
        <origin xyz="0 0 -0.12" rpy="0 0 0" />
        <inertia ixx="0.005" ixy="0.0" ixz="0.0" iyy="0.005" iyz="0.0" izz="0.003" />
      </inertial>
      <visual>
        <origin xyz="0 0 -0.12" rpy="0 0 0" />
        <geometry>
          <cylinder length="0.24" radius="0.04" />
        </geometry>
        <material name="blue">
          <color rgba="0 0 0.8 1.0" />
        </material>
      </visual>
      <collision>
        <origin xyz="0 0 -0.12" rpy="0 0 0" />
        <geometry>
          <cylinder length="0.24" radius="0.04" />
        </geometry>
      </collision>
    </link>

    <joint name="${prefix}_elbow_joint" type="revolute">
      <parent link="${prefix}_upper_arm" />
      <child link="${prefix}_lower_arm" />
      <origin xyz="0.0 0.0 -0.3" rpy="0 0 0" />
      <axis xyz="0 0 1" />
      <limit lower="${-M_PI/2}" upper="${M_PI/2}" effort="10" velocity="1.0" />
    </joint>

    <link name="${prefix}_hand">
      <inertial>
        <mass value="${arm_mass * 0.3}" />
        <origin xyz="0 0 -0.05" rpy="0 0 0" />
        <inertia ixx="0.001" ixy="0.0" ixz="0.0" iyy="0.001" iyz="0.0" izz="0.001" />
      </inertial>
      <visual>
        <origin xyz="0 0 -0.05" rpy="0 0 0" />
        <geometry>
          <box size="0.08 0.08 0.1" />
        </geometry>
        <material name="light_grey">
          <color rgba="0.7 0.7 0.7 1.0" />
        </material>
      </visual>
      <collision>
        <origin xyz="0 0 -0.05" rpy="0 0 0" />
        <geometry>
          <box size="0.08 0.08 0.1" />
        </geometry>
      </collision>
    </link>

    <joint name="${prefix}_wrist_joint" type="revolute">
      <parent link="${prefix}_lower_arm" />
      <child link="${prefix}_hand" />
      <origin xyz="0.0 0.0 -0.24" rpy="0 0 0" />
      <axis xyz="0 1 0" />
      <limit lower="${-M_PI/3}" upper="${M_PI/3}" effort="5" velocity="1.0" />
    </joint>
  </xacro:macro>

  <!-- Left Leg Macro -->
  <xacro:macro name="simple_leg" params="prefix parent *origin">
    <link name="${prefix}_upper_leg">
      <inertial>
        <mass value="${leg_mass}" />
        <origin xyz="0 0 -0.2" rpy="0 0 0" />
        <inertia ixx="0.05" ixy="0.0" ixz="0.0" iyy="0.05" iyz="0.0" izz="0.02" />
      </inertial>
      <visual>
        <origin xyz="0 0 -0.2" rpy="0 0 0" />
        <geometry>
          <cylinder length="0.4" radius="0.08" />
        </geometry>
        <material name="red">
          <color rgba="0.8 0 0 1.0" />
        </material>
      </visual>
      <collision>
        <origin xyz="0 0 -0.2" rpy="0 0 0" />
        <geometry>
          <cylinder length="0.4" radius="0.08" />
        </geometry>
      </collision>
    </link>

    <joint name="${prefix}_hip_joint" type="revolute">
      <parent link="${parent}" />
      <child link="${prefix}_upper_leg" />
      <xacro:insert_block name="origin" />
      <axis xyz="0 0 1" />
      <limit lower="${-M_PI/3}" upper="${M_PI/3}" effort="20" velocity="1.0" />
    </joint>

    <link name="${prefix}_lower_leg">
      <inertial>
        <mass value="${leg_mass * 0.8}" />
        <origin xyz="0 0 -0.2" rpy="0 0 0" />
        <inertia ixx="0.04" ixy="0.0" ixz="0.0" iyy="0.04" iyz="0.0" izz="0.015" />
      </inertial>
      <visual>
        <origin xyz="0 0 -0.2" rpy="0 0 0" />
        <geometry>
          <cylinder length="0.4" radius="0.07" />
        </geometry>
        <material name="red">
          <color rgba="0.8 0 0 1.0" />
        </material>
      </visual>
      <collision>
        <origin xyz="0 0 -0.2" rpy="0 0 0" />
        <geometry>
          <cylinder length="0.4" radius="0.07" />
        </geometry>
      </collision>
    </link>

    <joint name="${prefix}_knee_joint" type="revolute">
      <parent link="${prefix}_upper_leg" />
      <child link="${prefix}_lower_leg" />
      <origin xyz="0.0 0.0 -0.4" rpy="0 0 0" />
      <axis xyz="0 0 1" />
      <limit lower="0" upper="${M_PI/2}" effort="20" velocity="1.0" />
    </joint>

    <link name="${prefix}_foot">
      <inertial>
        <mass value="${leg_mass * 0.3}" />
        <origin xyz="0.05 0 -0.02" rpy="0 0 0" />
        <inertia ixx="0.002" ixy="0.0" ixz="0.0" iyy="0.003" iyz="0.0" izz="0.004" />
      </inertial>
      <visual>
        <origin xyz="0.05 0 -0.02" rpy="0 0 0" />
        <geometry>
          <box size="0.15 0.08 0.04" />
        </geometry>
        <material name="dark_grey">
          <color rgba="0.3 0.3 0.3 1.0" />
        </material>
      </visual>
      <collision>
        <origin xyz="0.05 0 -0.02" rpy="0 0 0" />
        <geometry>
          <box size="0.15 0.08 0.04" />
        </geometry>
      </collision>
    </link>

    <joint name="${prefix}_ankle_joint" type="revolute">
      <parent link="${prefix}_lower_leg" />
      <child link="${prefix}_foot" />
      <origin xyz="0.0 0.0 -0.4" rpy="0 0 0" />
      <axis xyz="0 1 0" />
      <limit lower="${-M_PI/6}" upper="${M_PI/6}" effort="10" velocity="0.5" />
    </joint>
  </xacro:macro>

  <!-- Left Arm -->
  <xacro:simple_arm prefix="left" parent="torso">
    <origin xyz="0.15 0.1 0.3" rpy="0 0 0" />
  </xacro:simple_arm>

  <!-- Right Arm -->
  <xacro:simple_arm_right prefix="right" parent="torso">
    <origin xyz="0.15 -0.1 0.3" rpy="0 0 0" />
  </xacro:simple_arm_right>

  <!-- Left Leg -->
  <xacro:simple_leg prefix="left" parent="torso">
    <origin xyz="-0.1 0.08 0.0" rpy="0 0 0" />
  </xacro:simple_leg>

  <!-- Right Leg -->
  <xacro:simple_leg prefix="right" parent="torso">
    <origin xyz="-0.1 -0.08 0.0" rpy="0 0 0" />
  </xacro:simple_leg>

  <!-- Sensors -->
  <link name="imu_link">
    <inertial>
      <mass value="0.1" />
      <origin xyz="0 0 0" />
      <inertia ixx="0.0001" ixy="0" ixz="0" iyy="0.0001" iyz="0" izz="0.0001" />
    </inertial>
  </link>
  <joint name="imu_joint" type="fixed">
    <parent link="torso" />
    <child link="imu_link" />
    <origin xyz="0 0 0.1" rpy="0 0 0" />
  </joint>

  <link name="camera_link">
    <inertial>
      <mass value="0.1" />
      <origin xyz="0 0 0" />
      <inertia ixx="0.0001" ixy="0" ixz="0" iyy="0.0001" iyz="0" izz="0.0001" />
    </inertial>
    <visual>
      <origin xyz="0 0 0" rpy="0 0 0" />
      <geometry>
        <box size="0.02 0.04 0.01" />
      </geometry>
      <material name="black">
        <color rgba="0 0 0 1" />
      </material>
    </visual>
  </link>
  <joint name="camera_joint" type="fixed">
    <parent link="head" />
    <child link="camera_link" />
    <origin xyz="0.05 0 0.05" rpy="0 0 0" />
  </joint>

  <!-- Gazebo plugins -->
  <gazebo reference="base_link">
    <material>Gazebo/Grey</material>
  </gazebo>

  <gazebo reference="torso">
    <material>Gazebo/Grey</material>
  </gazebo>

  <gazebo reference="head">
    <material>Gazebo/White</material>
  </gazebo>

  <gazebo reference="left_upper_arm">
    <material>Gazebo/Blue</material>
  </gazebo>

  <gazebo reference="right_upper_arm">
    <material>Gazebo/Blue</material>
  </gazebo>

  <gazebo reference="left_lower_arm">
    <material>Gazebo/Blue</material>
  </gazebo>

  <gazebo reference="right_lower_arm">
    <material>Gazebo/Blue</material>
  </gazebo>

  <gazebo reference="left_hand">
    <material>Gazebo/Grey</material>
  </gazebo>

  <gazebo reference="right_hand">
    <material>Gazebo/Grey</material>
  </gazebo>

  <gazebo reference="left_upper_leg">
    <material>Gazebo/Red</material>
  </gazebo>

  <gazebo reference="right_upper_leg">
    <material>Gazebo/Red</material>
  </gazebo>

  <gazebo reference="left_lower_leg">
    <material>Gazebo/Red</material>
  </gazebo>

  <gazebo reference="right_lower_leg">
    <material>Gazebo/Red</material>
  </gazebo>

  <gazebo reference="left_foot">
    <material>Gazebo/Black</material>
  </gazebo>

  <gazebo reference="right_foot">
    <material>Gazebo/Black</material>
  </gazebo>

  <!-- Gazebo plugins for sensors -->
  <gazebo reference="imu_link">
    <sensor name="imu_sensor" type="imu">
      <always_on>true</always_on>
      <update_rate>100</update_rate>
      <visualize>true</visualize>
    </sensor>
  </gazebo>

  <gazebo reference="camera_link">
    <sensor name="camera" type="camera">
      <always_on>true</always_on>
      <update_rate>30</update_rate>
      <camera name="head">
        <horizontal_fov>1.3962634</horizontal_fov>
        <image>
          <width>800</width>
          <height>600</height>
          <format>R8G8B8</format>
        </image>
        <clip>
          <near>0.1</near>
          <far>100</far>
        </clip>
      </camera>
      <plugin name="camera_controller" filename="libgazebo_ros_camera.so">
        <frame_name>camera_link</frame_name>
      </plugin>
    </sensor>
  </gazebo>

</robot>